Workbook

Sheet semi-elasticities
A1: D2020 | B1: -0.096 | C1: =(EXP(B1)-1) -> -0.091535984
A2: DIPI | B2: -0.035 | C2: =(EXP(B2)-1) -> -0.034394584
A3: DNO | B3: 0.071 | C3: =(EXP(B3)-1) -> 0.073581226
A4: DNE | B4: -0.213 | C4: =(EXP(B4)-1) -> -0.19184386
A5: DSE | B5: -0.154 | C5: =(EXP(B5)-1) -> -0.14272798
A6: DCW | B6: 0.056 | C6: =(EXP(B6)-1) -> 0.057597684

Sheet state-ids
A1: State ID | B1: State | C1: Std | D1: Rho | E1: Rank Std | F1: Rank Rho | G1: Macro-região
A2: 11 | B2: RO | C2: 0.028272428 | D2: 0.69170743 | E2: =_xlfn.RANK.EQ(C2,C$2:C$28) -> 22 | F2: =_xlfn.RANK.EQ(D2,D$2:D$28) -> 21 | G2: =_xlfn.FLOOR.MATH(A2/10) -> 1
A3: 12 | B3: AC | C3: 0.037075564 | D3: 0.64969057 | E3: =_xlfn.RANK.EQ(C3,C$2:C$28) -> 18 | F3: =_xlfn.RANK.EQ(D3,D$2:D$28) -> 22 | G3: =_xlfn.FLOOR.MATH(A3/10) -> 1
A4: 13 | B4: AM | C4: 0.043542843 | D4: 0.91871452 | E4: =_xlfn.RANK.EQ(C4,C$2:C$28) -> 12 | F4: =_xlfn.RANK.EQ(D4,D$2:D$28) -> 4 | G4: =_xlfn.FLOOR.MATH(A4/10) -> 1
A5: 14 | B5: RR | C5: 0.048828349 | D5: 0.9421007 | E5: =_xlfn.RANK.EQ(C5,C$2:C$28) -> 9 | F5: =_xlfn.RANK.EQ(D5,D$2:D$28) -> 3 | G5: =_xlfn.FLOOR.MATH(A5/10) -> 1
A6: 15 | B6: PA | C6: 0.027161859 | D6: 0.79491878 | E6: =_xlfn.RANK.EQ(C6,C$2:C$28) -> 25 | F6: =_xlfn.RANK.EQ(D6,D$2:D$28) -> 13 | G6: =_xlfn.FLOOR.MATH(A6/10) -> 1
A7: 16 | B7: AP | C7: 0.040092234 | D7: 0.72732532 | E7: =_xlfn.RANK.EQ(C7,C$2:C$28) -> 16 | F7: =_xlfn.RANK.EQ(D7,D$2:D$28) -> 18 | G7: =_xlfn.FLOOR.MATH(A7/10) -> 1
A8: 17 | B8: TO | C8: 0.043023501 | D8: 0.85814005 | E8: =_xlfn.RANK.EQ(C8,C$2:C$28) -> 14 | F8: =_xlfn.RANK.EQ(D8,D$2:D$28) -> 11 | G8: =_xlfn.FLOOR.MATH(A8/10) -> 1
A9: 21 | B9: MA | C9: 0.030837322 | D9: 0.88261569 | E9: =_xlfn.RANK.EQ(C9,C$2:C$28) -> 20 | F9: =_xlfn.RANK.EQ(D9,D$2:D$28) -> 7 | G9: =_xlfn.FLOOR.MATH(A9/10) -> 2
A10: 22 | B10: PI | C10: 0.029989334 | D10: 0.87431186 | E10: =_xlfn.RANK.EQ(C10,C$2:C$28) -> 21 | F10: =_xlfn.RANK.EQ(D10,D$2:D$28) -> 9 | G10: =_xlfn.FLOOR.MATH(A10/10) -> 2
A11: 23 | B11: CE | C11: 0.035185255 | D11: 0.94621211 | E11: =_xlfn.RANK.EQ(C11,C$2:C$28) -> 19 | F11: =_xlfn.RANK.EQ(D11,D$2:D$28) -> 2 | G11: =_xlfn.FLOOR.MATH(A11/10) -> 2
A12: 24 | B12: RN | C12: 0.025197597 | D12: 0.49093872 | E12: =_xlfn.RANK.EQ(C12,C$2:C$28) -> 27 | F12: =_xlfn.RANK.EQ(D12,D$2:D$28) -> 25 | G12: =_xlfn.FLOOR.MATH(A12/10) -> 2
A13: 25 | B13: PB | C13: 0.026058933 | D13: 0.63557994 | E13: =_xlfn.RANK.EQ(C13,C$2:C$28) -> 26 | F13: =_xlfn.RANK.EQ(D13,D$2:D$28) -> 23 | G13: =_xlfn.FLOOR.MATH(A13/10) -> 2
... A28: 53 | B28: DF | C28: 0.045714077 | D28: 0.90451354 | E28: =_xlfn.RANK.EQ(C28,C$2:C$28) -> 11 | F28: =_xlfn.RANK.EQ(D28,D$2:D$28) -> 5 | G28: =_xlfn.FLOOR.MATH(A28/10) -> 5

Sheet dataset
A1: i | B1: t | C1: ln_Sg_pc | D1: ln_Pg | E1: ln_l1_Pg | F1: ln_l2_Pg | G1: ln_Pe | H1: ln_l1_Pe | I1: ln_l2_Pe | J1: ln_Mi_e | K1: ln_W_adj_Mi_e | L1: ln_Mi_c | M1: ln_gdp_pc | N1: ln_l1_gdp_pc | O1: ln_stations | P1: d_ln_gdp | Q1: ipi_red | R1: y2020 | S1: d_CW | T1: d_SO | U1: d_SE | V1: d_NE | W1: d_NO | X1: pred | Y1: y | Z1: y_hat | AA1: eps | AB1: eps2 | AC1: State | AD1: Deviation | AE1: Rho | AF1: Rho*(ln(y) -ln( y_hat)) | AG1: Pred+ | AH1: Pred- | AI1: Upper
A2: 11 | B2: 2006 | C2: -2.156699 | D2: 1.0043016 | E2: 0.97482376 | F2: 0.96172288 | G2: 0.76080583 | H2: 0.62422574 | I2: 0.56246886 | J2: -11.512925 | K2: 2.1662502 | L2: -1.9511677 | M2: 2.4209188 | N2: 2.4439902 | O2: -11.512925 | P2: -0.023071492 | Q2: 0 | R2: 0 | S2: 0 | T2: 0 | U2: 0 | V2: 0 | W2: 1 | X2: -2.2191131 | Y2: =EXP(C2) -> 0.11570644 | Z2: =EXP(X2) -> 0.10870548 | AA2: =Y2-Z2 -> 0.007000965 | AB2: =AA2*AA2 -> 4.9013511e-05 | AC2: =VLOOKUP(A2, 'state-ids'!$A$1:$B$28, 2) -> RO | AD2: =VLOOKUP(A2, 'state-ids'!$A$1:$C$28, 3) -> 0.028272428 | AE2: =VLOOKUP(A2, 'state-ids'!$A$1:$D$28, 4) -> 0.69170743 | AF2: =IF(B2=2006, (C2-X2)*SQRT(1 - AE2*AE2), AE2*(C2-X2) ) -> 0.045074103 | AG2: =EXP(X2+SQRT((AD2*AD2)/(1-(AE2*AE2)))) -> 0.11304557 | AH2: =EXP(X2-SQRT((AD2*AD2)/(1-(AE2*AE2)))) -> 0.10453201 | AI2: =AG2-AH2 -> 0.0085135619
A3: 11 | B3: 2007 | C3: -2.0736364 | D3: 0.94219237 | E3: 1.0043016 | F3: 0.97482376 | G3: 0.59823192 | H3: 0.76080583 | I3: 0.62422574 | J3: -11.512925 | K3: 2.1662502 | L3: -1.79915 | M3: 2.4815372 | N3: 2.4431989 | O3: -11.512925 | P3: 0.038338222 | Q3: 0 | R3: 0 | S3: 0 | T3: 0 | U3: 0 | V3: 0 | W3: 1 | X3: -2.0994787 | Y3: =EXP(C3) -> 0.12572775 | Z3: =EXP(X3) -> 0.12252028 | AA3: =Y3-Z3 -> 0.0032074709 | AB3: =AA3*AA3 -> 1.028787e-05 | AC3: =VLOOKUP(A3, 'state-ids'!$A$1:$B$28, 2) -> RO | AD3: =VLOOKUP(A3, 'state-ids'!$A$1:$C$28, 3) -> 0.028272428 | AE3: =VLOOKUP(A3, 'state-ids'!$A$1:$D$28, 4) -> 0.69170743 | AF3: =IF(B3=2006, (C3-X3)*SQRT(1 - AE3*AE3), AE3*(C3-X3) ) -> 0.017875308 | AG3: =EXP(X3+SQRT((AD3*AD3)/(1-(AE3*AE3)))) -> 0.12741193 | AH3: =EXP(X3-SQRT((AD3*AD3)/(1-(AE3*AE3)))) -> 0.11781643 | AI3: =AG3-AH3 -> 0.0095955053
A4: 11 | B4: 2008 | C4: -1.9560619 | D4: 0.89600639 | E4: 0.94219237 | F4: 1.0043016 | G4: 0.51962678 | H4: 0.59823192 | I4: 0.76080583 | J4: -11.512925 | K4: 2.1662502 | L4: -1.6207635 | M4: 2.6001618 | N4: 2.5043251 | O4: -11.512925 | P4: 0.095836766 | Q4: 0 | R4: 0 | S4: 0 | T4: 0 | U4: 0 | V4: 0 | W4: 1 | X4: -1.9737296 | Y4: =EXP(C4) -> 0.14141423 | Z4: =EXP(X4) -> 0.13893771 | AA4: =Y4-Z4 -> 0.0024765218 | AB4: =AA4*AA4 -> 6.1331605e-06 | AC4: =VLOOKUP(A4, 'state-ids'!$A$1:$B$28, 2) -> RO | AD4: =VLOOKUP(A4, 'state-ids'!$A$1:$C$28, 3) -> 0.028272428 | AE4: =VLOOKUP(A4, 'state-ids'!$A$1:$D$28, 4) -> 0.69170743 | AF4: =IF(B4=2006, (C4-X4)*SQRT(1 - AE4*AE4), AE4*(C4-X4) ) -> 0.012220876 | AG4: =EXP(X4+SQRT((AD4*AD4)/(1-(AE4*AE4)))) -> 0.14448483 | AH4: =EXP(X4-SQRT((AD4*AD4)/(1-(AE4*AE4)))) -> 0.13360355 | AI4: =AG4-AH4 -> 0.01088128
A5: 11 | B5: 2009 | C5: -1.8621541 | D5: 0.84264419 | E5: 0.89600639 | F5: 0.94219237 | G5: 0.47741361 | H5: 0.51962678 | I5: 0.59823192 | J5: -7.3158356 | K5: 2.1662502 | L5: -1.4770533 | M5: 2.6546802 | N5: 2.5932474 | O5: -11.512925 | P5: 0.061432835 | Q5: 0 | R5: 0 | S5: 0 | T5: 0 | U5: 0 | V5: 0 | W5: 1 | X5: -1.8739249 | Y5: =EXP(C5) -> 0.15533765 | Z5: =EXP(X5) -> 0.15351993 | AA5: =Y5-Z5 -> 0.0018177143 | AB5: =AA5*AA5 -> 3.3040851e-06 | AC5: =VLOOKUP(A5, 'state-ids'!$A$1:$B$28, 2) -> RO | AD5: =VLOOKUP(A5, 'state-ids'!$A$1:$C$28, 3) -> 0.028272428 | AE5: =VLOOKUP(A5, 'state-ids'!$A$1:$D$28, 4) -> 0.69170743 | AF5: =IF(B5=2006, (C5-X5)*SQRT(1 - AE5*AE5), AE5*(C5-X5) ) -> 0.0081418818 | AG5: =EXP(X5+SQRT((AD5*AD5)/(1-(AE5*AE5)))) -> 0.15964926 | AH5: =EXP(X5-SQRT((AD5*AD5)/(1-(AE5*AE5)))) -> 0.14762593 | AI5: =AG5-AH5 -> 0.012023327
A6: 11 | B6: 2010 | C6: -1.6831605 | D6: 0.81828091 | E6: 0.84264419 | F6: 0.89600639 | G6: 0.52212158 | H6: 0.47741361 | I6: 0.51962678 | J6: -7.3396624 | K6: 2.1662502 | L6: -1.362601 | M6: 2.7423013 | N6: 2.6308535 | O6: -11.512925 | P6: 0.11144786 | Q6: 0 | R6: 0 | S6: 0 | T6: 0 | U6: 0 | V6: 0 | W6: 1 | X6: -1.7428951 | Y6: =EXP(C6) -> 0.18578586 | Z6: =EXP(X6) -> 0.17501298 | AA6: =Y6-Z6 -> 0.010772881 | AB6: =AA6*AA6 -> 0.00011605497 | AC6: =VLOOKUP(A6, 'state-ids'!$A$1:$B$28, 2) -> RO | AD6: =VLOOKUP(A6, 'state-ids'!$A$1:$C$28, 3) -> 0.028272428 | AE6: =VLOOKUP(A6, 'state-ids'!$A$1:$D$28, 4) -> 0.69170743 | AF6: =IF(B6=2006, (C6-X6)*SQRT(1 - AE6*AE6), AE6*(C6-X6) ) -> 0.041318856 | AG6: =EXP(X6+SQRT((AD6*AD6)/(1-(AE6*AE6)))) -> 0.18200042 | AH6: =EXP(X6-SQRT((AD6*AD6)/(1-(AE6*AE6)))) -> 0.16829381 | AI6: =AG6-AH6 -> 0.013706613
A7: 11 | B7: 2011 | C7: -1.5784624 | D7: 0.82162834 | E7: 0.81828091 | F7: 0.84264419 | G7: 0.59933088 | H7: 0.52212158 | I7: 0.47741361 | J7: -5.2834924 | K7: 2.1662502 | L7: -1.2610803 | M7: 2.7818139 | N7: 2.7190297 | O7: -11.512925 | P7: 0.062784165 | Q7: 0 | R7: 0 | S7: 0 | T7: 0 | U7: 0 | V7: 0 | W7: 1 | X7: -1.6322517 | Y7: =EXP(C7) -> 0.20629204 | Z7: =EXP(X7) -> 0.19548889 | AA7: =Y7-Z7 -> 0.010803153 | AB7: =AA7*AA7 -> 0.00011670812 | AC7: =VLOOKUP(A7, 'state-ids'!$A$1:$B$28, 2) -> RO | AD7: =VLOOKUP(A7, 'state-ids'!$A$1:$C$28, 3) -> 0.028272428 | AE7: =VLOOKUP(A7, 'state-ids'!$A$1:$D$28, 4) -> 0.69170743 | AF7: =IF(B7=2006, (C7-X7)*SQRT(1 - AE7*AE7), AE7*(C7-X7) ) -> 0.03720646 | AG7: =EXP(X7+SQRT((AD7*AD7)/(1-(AE7*AE7)))) -> 0.20329383 | AH7: =EXP(X7-SQRT((AD7*AD7)/(1-(AE7*AE7)))) -> 0.18798359 | AI7: =AG7-AH7 -> 0.015310238
A8: 11 | B8: 2012 | C8: -1.4705849 | D8: 0.76150652 | E8: 0.82162834 | F8: 0.81828091 | G8: 0.55933003 | H8: 0.59933088 | I8: 0.52212158 | J8: -4.8865896 | K8: 2.1662502 | L8: -1.1711676 | M8: 2.7848658 | N8: 2.7732516 | O8: -11.512925 | P8: 0.01161418 | Q8: 0 | R8: 0 | S8: 0 | T8: 0 | U8: 0 | V8: 0 | W8: 1 | X8: -1.5097338 | Y8: =EXP(C8) -> 0.22979105 | Z8: =EXP(X8) -> 0.22096879 | AA8: =Y8-Z8 -> 0.0088222526 | AB8: =AA8*AA8 -> 7.7832141e-05 | AC8: =VLOOKUP(A8, 'state-ids'!$A$1:$B$28, 2) -> RO | AD8: =VLOOKUP(A8, 'state-ids'!$A$1:$C$28, 3) -> 0.028272428 | AE8: =VLOOKUP(A8, 'state-ids'!$A$1:$D$28, 4) -> 0.69170743 | AF8: =IF(B8=2006, (C8-X8)*SQRT(1 - AE8*AE8), AE8*(C8-X8) ) -> 0.027079596 | AG8: =EXP(X8+SQRT((AD8*AD8)/(1-(AE8*AE8)))) -> 0.22979103 | AH8: =EXP(X8-SQRT((AD8*AD8)/(1-(AE8*AE8)))) -> 0.21248526 | AI8: =AG8-AH8 -> 0.017305766
A9: 11 | B9: 2013 | C9: -1.5187256 | D9: 0.74069848 | E9: 0.76150652 | F9: 0.82162834 | G9: 0.51837704 | H9: 0.55933003 | I9: 0.59933088 | J9: -4.235968 | K9: 2.1662502 | L9: -1.178268 | M9: 2.6621035 | N9: 2.7015182 | O9: -11.512925 | P9: -0.039414693 | Q9: 0 | R9: 0 | S9: 0 | T9: 0 | U9: 0 | V9: 0 | W9: 1 | X9: -1.5056479 | Y9: =EXP(C9) -> 0.21899079 | Z9: =EXP(X9) -> 0.2218735 | AA9: =Y9-Z9 -> -0.0028827054 | AB9: =AA9*AA9 -> 8.3099906e-06 | AC9: =VLOOKUP(A9, 'state-ids'!$A$1:$B$28, 2) -> RO | AD9: =VLOOKUP(A9, 'state-ids'!$A$1:$C$28, 3) -> 0.028272428 | AE9: =VLOOKUP(A9, 'state-ids'!$A$1:$D$28, 4) -> 0.69170743 | AF9: =IF(B9=2006, (C9-X9)*SQRT(1 - AE9*AE9), AE9*(C9-X9) ) -> -0.0090459456 | AG9: =EXP(X9+SQRT((AD9*AD9)/(1-(AE9*AE9)))) -> 0.23073185 | AH9: =EXP(X9-SQRT((AD9*AD9)/(1-(AE9*AE9)))) -> 0.21335523 | AI9: =AG9-AH9 -> 0.01737662
A10: 11 | B10: 2014 | C10: -1.4578474 | D10: 0.72328834 | E10: 0.74069848 | F10: 0.76150652 | G10: 0.52715163 | H10: 0.51837704 | I10: 0.55933003 | J10: -3.5545083 | K10: 2.1662502 | L10: -1.1213793 | M10: 2.6642506 | N10: 2.650416 | O10: -11.512925 | P10: 0.013834563 | Q10: 0 | R10: 0 | S10: 0 | T10: 0 | U10: 0 | V10: 0 | W10: 1 | X10: -1.4344883 | Y10: =EXP(C10) -> 0.23273672 | Z10: =EXP(X10) -> 0.23823724 | AA10: =Y10-Z10 -> -0.0055005195 | AB10: =AA10*AA10 -> 3.0255715e-05 | AC10: =VLOOKUP(A10, 'state-ids'!$A$1:$B$28, 2) -> RO | AD10: =VLOOKUP(A10, 'state-ids'!$A$1:$C$28, 3) -> 0.028272428 | AE10: =VLOOKUP(A10, 'state-ids'!$A$1:$D$28, 4) -> 0.69170743 | AF10: =IF(B10=2006, (C10-X10)*SQRT(1 - AE10*AE10), AE10*(C10-X10) ) -> -0.01615768 | AG10: =EXP(X10+SQRT((AD10*AD10)/(1-(AE10*AE10)))) -> 0.24774892 | AH10: =EXP(X10-SQRT((AD10*AD10)/(1-(AE10*AE10)))) -> 0.22909073 | AI10: =AG10-AH10 -> 0.018658191
A11: 11 | B11: 2015 | C11: -1.4449811 | D11: 0.7369248 | E11: 0.72328834 | F11: 0.74069848 | G11: 0.47759971 | H11: 0.52715163 | I11: 0.51837704 | J11: -3.1339142 | K11: 2.1662502 | L11: -1.0788236 | M11: 2.6519008 | N11: 2.6530623 | O11: -11.512925 | P11: -0.001161491 | Q11: 1 | R11: 0 | S11: 0 | T11: 0 | U11: 0 | V11: 0 | W11: 1 | X11: -1.4744012 | Y11: =EXP(C11) -> 0.23575053 | Z11: =EXP(X11) -> 0.22891575 | AA11: =Y11-Z11 -> 0.0068347773 | AB11: =AA11*AA11 -> 4.6714181e-05 | AC11: =VLOOKUP(A11, 'state-ids'!$A$1:$B$28, 2) -> RO | AD11: =VLOOKUP(A11, 'state-ids'!$A$1:$C$28, 3) -> 0.028272428 | AE11: =VLOOKUP(A11, 'state-ids'!$A$1:$D$28, 4) -> 0.69170743 | AF11: =IF(B11=2006, (C11-X11)*SQRT(1 - AE11*AE11), AE11*(C11-X11) ) -> 0.02035012 | AG11: =EXP(X11+SQRT((AD11*AD11)/(1-(AE11*AE11)))) -> 0.23805527 | AH11: =EXP(X11-SQRT((AD11*AD11)/(1-(AE11*AE11)))) -> 0.22012712 | AI11: =AG11-AH11 -> 0.017928153
A12: 11 | B12: 2016 | C12: -1.4210112 | D12: 0.75358355 | E12: 0.7369248 | F12: 0.72328834 | G12: 0.61858526 | H12: 0.47759971 | I12: 0.52715163 | J12: -2.7610618 | K12: 2.1662502 | L12: -1.049732 | M12: 2.6395016 | N12: 2.6411708 | O12: -11.512925 | P12: -0.0016691901 | Q12: 1 | R12: 0 | S12: 0 | T12: 0 | U12: 0 | V12: 0 | W12: 1 | X12: -1.4142199 | Y12: =EXP(C12) -> 0.24146971 | Z12: =EXP(X12) -> 0.2431152 | AA12: =Y12-Z12 -> -0.0016454953 | AB12: =AA12*AA12 -> 2.7076548e-06 | AC12: =VLOOKUP(A12, 'state-ids'!$A$1:$B$28, 2) -> RO | AD12: =VLOOKUP(A12, 'state-ids'!$A$1:$C$28, 3) -> 0.028272428 | AE12: =VLOOKUP(A12, 'state-ids'!$A$1:$D$28, 4) -> 0.69170743 | AF12: =IF(B12=2006, (C12-X12)*SQRT(1 - AE12*AE12), AE12*(C12-X12) ) -> -0.0046976523 | AG12: =EXP(X12+SQRT((AD12*AD12)/(1-(AE12*AE12)))) -> 0.25282164 | AH12: =EXP(X12-SQRT((AD12*AD12)/(1-(AE12*AE12)))) -> 0.23378142 | AI12: =AG12-AH12 -> 0.019040221
A13: 11 | B13: 2017 | C13: -1.4207559 | D13: 0.74241342 | E13: 0.75358355 | F13: 0.7369248 | G13: 0.60704448 | H13: 0.61858526 | I13: 0.47759971 | J13: -2.0826519 | K13: 2.1662502 | L13: -1.0245114 | M13: 2.6909784 | N13: 2.6291989 | O13: -11.512925 | P13: 0.061779521 | Q13: 1 | R13: 0 | S13: 0 | T13: 0 | U13: 0 | V13: 0 | W13: 1 | X13: -1.3754632 | Y13: =EXP(C13) -> 0.24153136 | Z13: =EXP(X13) -> 0.2527225 | AA13: =Y13-Z13 -> -0.011191131 | AB13: =AA13*AA13 -> 0.00012524141 | AC13: =VLOOKUP(A13, 'state-ids'!$A$1:$B$28, 2) -> RO | AD13: =VLOOKUP(A13, 'state-ids'!$A$1:$C$28, 3) -> 0.028272428 | AE13: =VLOOKUP(A13, 'state-ids'!$A$1:$D$28, 4) -> 0.69170743 | AF13: =IF(B13=2006, (C13-X13)*SQRT(1 - AE13*AE13), AE13*(C13-X13) ) -> -0.031329292 | AG13: =EXP(X13+SQRT((AD13*AD13)/(1-(AE13*AE13)))) -> 0.26281251 | AH13: =EXP(X13-SQRT((AD13*AD13)/(1-(AE13*AE13)))) -> 0.24301986 | AI13: =AG13-AH13 -> 0.019792642
... A487: 53 | B487: 2023 | C487: -1.0745403 | D487: 0.74379277 | E487: 0.92271008 | F487: 0.93969471 | G487: 0.3936624 | H487: 0.70275092 | I487: 0.74900753 | J487: 1.9260339 | K487: 0.60717368 | L487: -0.63910199 | M487: 3.8777847 | N487: 3.8217818 | O487: 8.4658999 | P487: 0.056002859 | Q487: 1 | R487: 0 | S487: 1 | T487: 0 | U487: 0 | V487: 0 | W487: 0 | X487: -1.1297326 | Y487: =EXP(C487) -> 0.34145468 | Z487: =EXP(X487) -> 0.32311964 | AA487: =Y487-Z487 -> 0.018335038 | AB487: =AA487*AA487 -> 0.00033617362 | AC487: =VLOOKUP(A487, 'state-ids'!$A$1:$B$28, 2) -> DF | AD487: =VLOOKUP(A487, 'state-ids'!$A$1:$C$28, 3) -> 0.045714077 | AE487: =VLOOKUP(A487, 'state-ids'!$A$1:$D$28, 4) -> 0.90451354 | AF487: =IF(B487=2006, (C487-X487)*SQRT(1 - AE487*AE487), AE487*(C487-X487) ) -> 0.049922181 | AG487: =EXP(X487+SQRT((AD487*AD487)/(1-(AE487*AE487)))) -> 0.35968216 | AH487: =EXP(X487-SQRT((AD487*AD487)/(1-(AE487*AE487)))) -> 0.29027379 | AI487: =AG487-AH487 -> 0.06940837

Sheet State preds
A2: State | B2: MS
A4: Year | B4: Lower | C4: Confidence 63% | D4: Predicted | E4: Actual
A5: 2006 | B5: 0.13521948 | C5: 0.016451374 | D5: 0.14320913 | E5: 0.13869006
A6: 2007 | B6: 0.14295513 | C6: 0.017392525 | D6: 0.15140185 | E6: 0.14197604
A7: 2008 | B7: 0.15591455 | C7: 0.018969224 | D7: 0.165127 | E7: 0.15254681
A8: 2009 | B8: 0.16681286 | C8: 0.020295158 | D8: 0.17666925 | E8: 0.15782185
A9: 2010 | B9: 0.18930415 | C9: 0.023031543 | D9: 0.20048947 | E9: 0.18655126
A10: 2011 | B10: 0.21403623 | C10: 0.026040553 | D10: 0.22668289 | E10: 0.22282756
A11: 2012 | B11: 0.23765459 | C11: 0.028914063 | D11: 0.25169677 | E11: 0.25726454
A12: 2013 | B12: 0.23924049 | C12: 0.029107009 | D12: 0.25337637 | E12: 0.25939192
A13: 2014 | B13: 0.24896135 | C13: 0.030289691 | D13: 0.26367161 | E13: 0.27398252
A14: 2015 | B14: 0.24164017 | C14: 0.029398964 | D14: 0.25591784 | E14: 0.25035632
A15: 2016 | B15: 0.26421596 | C15: 0.03214563 | D15: 0.27982755 | E15: 0.27657169
A16: 2017 | B16: 0.27469776 | C16: 0.033420891 | D16: 0.29092869 | E16: 0.28255872
... A22: 2023 | B22: 0.2619191 | C22: 0.031866184 | D22: 0.27739498 | E22: 0.28710324
A23: Grand Total | B23: 0.22602066 | C23: 0.027498629 | D23: 0.23937543 | E23: 0.23228388

Sheet Pivot - real values
A1: i | B1: t | C1: S | D1: Pg | E1: Pe | F1: GDP | G1: Mc | H1: Me | J1: Year | K1: Gasoline sales per capita | L1: Gasoline price | M1: Ethanol price | N1: GDP per capita | O1: Motorization index | P1: Motorization index (EV)
A2: =dataset!A2 -> 11 | B2: =dataset!B2 -> 2006 | C2: =EXP(dataset!C2) -> 0.11570644 | D2: =EXP(dataset!D2) -> 2.73 | E2: =EXP(dataset!G2) -> 2.14 | F2: =1000*EXP(dataset!M2) -> 11256.196 | G2: =EXP(dataset!L2) -> 0.14210803 | H2: =EXP(dataset!J2) -> 1e-05 | J2: 2006 | K2: 0.1175124 | L2: 2.6540741 | M2: 1.9696296 | N2: 14461.965 | O2: 0.15173146 | P2: 1e-05
A3: =dataset!A3 -> 11 | B3: =dataset!B3 -> 2007 | C3: =EXP(dataset!C3) -> 0.12572775 | D3: =EXP(dataset!D3) -> 2.5656 | E3: =EXP(dataset!G3) -> 1.8189 | F3: =1000*EXP(dataset!M3) -> 11959.634 | G3: =EXP(dataset!L3) -> 0.16543946 | H3: =EXP(dataset!J3) -> 1e-05 | J3: 2007 | K3: 0.11945993 | L3: 2.4921852 | M3: 1.6777519 | N3: 15193.315 | O3: 0.16726531 | P3: 1e-05
A4: =dataset!A4 -> 11 | B4: =dataset!B4 -> 2008 | C4: =EXP(dataset!C4) -> 0.14141423 | D4: =EXP(dataset!D4) -> 2.4498 | E4: =EXP(dataset!G4) -> 1.6814 | F4: =1000*EXP(dataset!M4) -> 13465.917 | G4: =EXP(dataset!L4) -> 0.19774767 | H4: =EXP(dataset!J4) -> 1e-05 | J4: 2008 | K4: 0.12737279 | L4: 2.3550111 | M4: 1.6010259 | N4: 16119.569 | O4: 0.18520088 | P4: 2.4113296e-05
A5: =dataset!A5 -> 11 | B5: =dataset!B5 -> 2009 | C5: =EXP(dataset!C5) -> 0.15533765 | D5: =EXP(dataset!D5) -> 2.3225 | E5: =EXP(dataset!G5) -> 1.6119 | F5: =1000*EXP(dataset!M5) -> 14220.438 | G5: =EXP(dataset!L5) -> 0.22830947 | H5: =EXP(dataset!J5) -> 0.00066492545 | J5: 2009 | K5: 0.13110086 | L5: 2.2647519 | M5: 1.5358444 | N5: 16058.948 | O5: 0.20306488 | P5: 0.0002346121
A6: =dataset!A6 -> 11 | B6: =dataset!B6 -> 2010 | C6: =EXP(dataset!C6) -> 0.18578586 | D6: =EXP(dataset!D6) -> 2.2666 | E6: =EXP(dataset!G6) -> 1.6856 | F6: =1000*EXP(dataset!M6) -> 15522.667 | G6: =EXP(dataset!L6) -> 0.25599406 | H6: =EXP(dataset!J6) -> 0.0006492697 | J6: 2010 | K6: 0.15492585 | L6: 2.1783889 | M6: 1.5843963 | N6: 17150.122 | O6: 0.22281867 | P6: 0.00054565174
A7: =dataset!A7 -> 11 | B7: =dataset!B7 -> 2011 | C7: =EXP(dataset!C7) -> 0.20629204 | D7: =EXP(dataset!D7) -> 2.2742 | E7: =EXP(dataset!G7) -> 1.8209 | F7: =1000*EXP(dataset!M7) -> 16148.286 | G7: =EXP(dataset!L7) -> 0.28334776 | H7: =EXP(dataset!J7) -> 0.005074677 | J7: 2011 | K7: 0.17681577 | L7: 2.1364889 | M7: 1.6923074 | N7: 17767.956 | O7: 0.24231468 | P7: 0.0031126515
A8: =dataset!A8 -> 11 | B8: =dataset!B8 -> 2012 | C8: =EXP(dataset!C8) -> 0.22979105 | D8: =EXP(dataset!D8) -> 2.1415 | E8: =EXP(dataset!G8) -> 1.7495 | F8: =1000*EXP(dataset!M8) -> 16197.644 | G8: =EXP(dataset!L8) -> 0.31000477 | H8: =EXP(dataset!J8) -> 0.0075471176 | J8: 2012 | K8: 0.19892608 | L8: 2.0204889 | M8: 1.6150519 | N8: 17992.065 | O8: 0.26084556 | P8: 0.0046207476
A9: =dataset!A9 -> 11 | B9: =dataset!B9 -> 2013 | C9: =EXP(dataset!C9) -> 0.21899079 | D9: =EXP(dataset!D9) -> 2.0974 | E9: =EXP(dataset!G9) -> 1.6793 | F9: =1000*EXP(dataset!M9) -> 14326.394 | G9: =EXP(dataset!L9) -> 0.30781142 | H9: =EXP(dataset!J9) -> 0.014465801 | J9: 2013 | K9: 0.2014577 | L9: 1.9976148 | M9: 1.5856 | N9: 17769.658 | O9: 0.26988588 | P9: 0.010505889
A10: =dataset!A10 -> 11 | B10: =dataset!B10 -> 2014 | C10: =EXP(dataset!C10) -> 0.23273672 | D10: =EXP(dataset!D10) -> 2.0612 | E10: =EXP(dataset!G10) -> 1.6941 | F10: =1000*EXP(dataset!M10) -> 14357.186 | G10: =EXP(dataset!L10) -> 0.32583008 | H10: =EXP(dataset!J10) -> 0.028595432 | J10: 2014 | K10: 0.21624676 | L10: 1.9543259 | M10: 1.5733444 | N10: 17841.431 | O10: 0.28456799 | P10: 0.020774184
A11: =dataset!A11 -> 11 | B11: =dataset!B11 -> 2015 | C11: =EXP(dataset!C11) -> 0.23575053 | D11: =EXP(dataset!D11) -> 2.0895 | E11: =EXP(dataset!G11) -> 1.6122 | F11: =1000*EXP(dataset!M11) -> 14180.968 | G11: =EXP(dataset!L11) -> 0.33999527 | H11: =EXP(dataset!J11) -> 0.043547012 | J11: 2015 | K11: 0.20535221 | L11: 1.9900963 | M11: 1.5240481 | N11: 17114.824 | O11: 0.29564717 | P11: 0.0306736
A12: =dataset!A12 -> 11 | B12: =dataset!B12 -> 2016 | C12: =EXP(dataset!C12) -> 0.24146971 | D12: =EXP(dataset!D12) -> 2.1246 | E12: =EXP(dataset!G12) -> 1.8563 | F12: =1000*EXP(dataset!M12) -> 14006.221 | G12: =EXP(dataset!L12) -> 0.35003153 | H12: =EXP(dataset!J12) -> 0.0632246 | J12: 2016 | K12: 0.21182591 | L12: 2.0526222 | M12: 1.714537 | N12: 16493.657 | O12: 0.30318375 | P12: 0.043307735
A13: =dataset!A13 -> 11 | B13: =dataset!B13 -> 2017 | C13: =EXP(dataset!C13) -> 0.24153136 | D13: =EXP(dataset!D13) -> 2.101 | E13: =EXP(dataset!G13) -> 1.835 | F13: =1000*EXP(dataset!M13) -> 14746.096 | G13: =EXP(dataset!L13) -> 0.35897182 | H13: =EXP(dataset!J13) -> 0.12459934 | J13: 2017 | K13: 0.21485131 | L13: 2.0292593 | M13: 1.6957481 | N13: 16631.748 | O13: 0.3107347 | P13: 0.081952898
... A19: =dataset!A19 -> 11 | B19: =dataset!B19 -> 2023 | C19: =EXP(dataset!C19) -> 0.26344117 | D19: =EXP(dataset!D19) -> 2.3355 | E19: =EXP(dataset!G19) -> 1.8761 | F19: =1000*EXP(dataset!M19) -> 17220.573 | G19: =EXP(dataset!L19) -> 0.43556249 | H19: =EXP(dataset!J19) -> 4.1690584 | J19: 2023 | K19: 0.22057919 | L19: 2.158337 | M19: 1.6597815 | N19: 18311.345 | O19: 0.36307324 | P19: 2.4417685
A20: =dataset!A20 -> 12 | B20: =dataset!B20 -> 2006 | C20: =EXP(dataset!C20) -> 0.078825184 | D20: =EXP(dataset!D20) -> 2.94 | E20: =EXP(dataset!G20) -> 2.26 | F20: =1000*EXP(dataset!M20) -> 9146.1619 | G20: =EXP(dataset!L20) -> 0.085469787 | H20: =EXP(dataset!J20) -> 1e-05 | J20: Grand Total | K20: 0.18203375 | L20: 2.2069049 | M20: 1.7013864 | N20: 16882.99 | O20: 0.27445454 | P20: 0.31637907
A21: =dataset!A21 -> 12 | B21: =dataset!B21 -> 2007 | C21: =EXP(dataset!C21) -> 0.087781519 | D21: =EXP(dataset!D21) -> 2.7953 | E21: =EXP(dataset!G21) -> 1.9816 | F21: =1000*EXP(dataset!M21) -> 10109.169 | G21: =EXP(dataset!L21) -> 0.10025111 | H21: =EXP(dataset!J21) -> 1e-05
A22: =dataset!A22 -> 12 | B22: =dataset!B22 -> 2008 | C22: =EXP(dataset!C22) -> 0.10287387 | D22: =EXP(dataset!D22) -> 2.6848 | E22: =EXP(dataset!G22) -> 1.8983 | F22: =1000*EXP(dataset!M22) -> 10967.195 | G22: =EXP(dataset!L22) -> 0.11867073 | H22: =EXP(dataset!J22) -> 1e-05 | J22: Year | K22: Gasoline sales | L22: Gasoline price | M22: Ethanol price | N22: GDP per capita | O22: ICEV | P22: EV
A23: =dataset!A23 -> 12 | B23: =dataset!B23 -> 2009 | C23: =EXP(dataset!C23) -> 0.10956547 | D23: =EXP(dataset!D23) -> 2.5739 | E23: =EXP(dataset!G23) -> 1.8286 | F23: =1000*EXP(dataset!M23) -> 11621.234 | G23: =EXP(dataset!L23) -> 0.13887651 | H23: =EXP(dataset!J23) -> 1e-05 | J23: 2006 | K23: 0.1175124 | L23: 2.6540741 | M23: 1.9696296 | N23: 14461.965 | O23: 0.15173146 | P23: 1e-05
A24: =dataset!A24 -> 12 | B24: =dataset!B24 -> 2010 | C24: =EXP(dataset!C24) -> 0.13214972 | D24: =EXP(dataset!D24) -> 2.4466 | E24: =EXP(dataset!G24) -> 1.972 | F24: =1000*EXP(dataset!M24) -> 11606.611 | G24: =EXP(dataset!L24) -> 0.1570596 | H24: =EXP(dataset!J24) -> 0.0013912869 | J24: 2007 | K24: 0.11945993 | L24: 2.4921852 | M24: 1.6777519 | N24: 15193.315 | O24: 0.16726531 | P24: 1e-05
A25: =dataset!A25 -> 12 | B25: =dataset!B25 -> 2011 | C25: =EXP(dataset!C25) -> 0.14328883 | D25: =EXP(dataset!D25) -> 2.3895 | E25: =EXP(dataset!G25) -> 1.9131 | F25: =1000*EXP(dataset!M25) -> 11069.527 | G25: =EXP(dataset!L25) -> 0.17096918 | H25: =EXP(dataset!J25) -> 0.0066989467 | J25: 2008 | K25: 0.12737279 | L25: 2.3550111 | M25: 1.6010259 | N25: 16119.569 | O25: 0.18520088 | P25: 2.4113296e-05
A26: =dataset!A26 -> 12 | B26: =dataset!B26 -> 2012 | C26: =EXP(dataset!C26) -> 0.1566868 | D26: =EXP(dataset!D26) -> 2.2721 | E26: =EXP(dataset!G26) -> 1.8293 | F26: =1000*EXP(dataset!M26) -> 11426.988 | G26: =EXP(dataset!L26) -> 0.18606168 | H26: =EXP(dataset!J26) -> 0.010543157 | J26: 2009 | K26: 0.13110086 | L26: 2.2647519 | M26: 1.5358444 | N26: 16058.948 | O26: 0.20306488 | P26: 0.0002346121
A27: =dataset!A27 -> 12 | B27: =dataset!B27 -> 2013 | C27: =EXP(dataset!C27) -> 0.16141141 | D27: =EXP(dataset!D27) -> 2.2276 | E27: =EXP(dataset!G27) -> 1.8095 | F27: =1000*EXP(dataset!M27) -> 11756.188 | G27: =EXP(dataset!L27) -> 0.19767716 | H27: =EXP(dataset!J27) -> 0.025757827 | J27: 2010 | K27: 0.15492585 | L27: 2.1783889 | M27: 1.5843963 | N27: 17150.122 | O27: 0.22281867 | P27: 0.00054565174
A28: =dataset!A28 -> 12 | B28: =dataset!B28 -> 2014 | C28: =EXP(dataset!C28) -> 0.17485328 | D28: =EXP(dataset!D28) -> 2.1965 | E28: =EXP(dataset!G28) -> 1.8358 | F28: =1000*EXP(dataset!M28) -> 12565.756 | G28: =EXP(dataset!L28) -> 0.21030856 | H28: =EXP(dataset!J28) -> 0.055689083 | J28: 2011 | K28: 0.17681577 | L28: 2.1364889 | M28: 1.6923074 | N28: 17767.956 | O28: 0.24231468 | P28: 0.0031126515
A29: =dataset!A29 -> 12 | B29: =dataset!B29 -> 2015 | C29: =EXP(dataset!C29) -> 0.17455703 | D29: =EXP(dataset!D29) -> 2.235 | E29: =EXP(dataset!G29) -> 1.781 | F29: =1000*EXP(dataset!M29) -> 11626.955 | G29: =EXP(dataset!L29) -> 0.22112026 | H29: =EXP(dataset!J29) -> 0.078405701 | J29: 2012 | K29: 0.19892608 | L29: 2.0204889 | M29: 1.6150519 | N29: 17992.065 | O29: 0.26084556 | P29: 0.0046207476
A30: =dataset!A30 -> 12 | B30: =dataset!B30 -> 2016 | C30: =EXP(dataset!C30) -> 0.16752776 | D30: =EXP(dataset!D30) -> 2.2396 | E30: =EXP(dataset!G30) -> 1.8344 | F30: =1000*EXP(dataset!M30) -> 10683.985 | G30: =EXP(dataset!L30) -> 0.22779229 | H30: =EXP(dataset!J30) -> 0.1053035 | J30: 2013 | K30: 0.2014577 | L30: 1.9976148 | M30: 1.5856 | N30: 17769.658 | O30: 0.26988588 | P30: 0.010505889
A31: =dataset!A31 -> 12 | B31: =dataset!B31 -> 2017 | C31: =EXP(dataset!C31) -> 0.16464493 | D31: =EXP(dataset!D31) -> 2.3244 | E31: =EXP(dataset!G31) -> 1.9414 | F31: =1000*EXP(dataset!M31) -> 10527.571 | G31: =EXP(dataset!L31) -> 0.23460649 | H31: =EXP(dataset!J31) -> 0.19406499 | J31: 2014 | K31: 0.21624676 | L31: 1.9543259 | M31: 1.5733444 | N31: 17841.431 | O31: 0.28456799 | P31: 0.020774184
A32: =dataset!A32 -> 12 | B32: =dataset!B32 -> 2018 | C32: =EXP(dataset!C32) -> 0.15400634 | D32: =EXP(dataset!D32) -> 2.5531 | E32: =EXP(dataset!G32) -> 2.0148 | F32: =1000*EXP(dataset!M32) -> 10328.226 | G32: =EXP(dataset!L32) -> 0.23516074 | H32: =EXP(dataset!J32) -> 0.28069691 | J32: 2015 | K32: 0.20535221 | L32: 1.9900963 | M32: 1.5240481 | N32: 17114.824 | O32: 0.29564717 | P32: 0.0306736
A33: =dataset!A33 -> 12 | B33: =dataset!B33 -> 2019 | C33: =EXP(dataset!C33) -> 0.1564757 | D33: =EXP(dataset!D33) -> 2.3837 | E33: =EXP(dataset!G33) -> 1.9414 | F33: =1000*EXP(dataset!M33) -> 9957.677 | G33: =EXP(dataset!L33) -> 0.24317212 | H33: =EXP(dataset!J33) -> 0.55899811 | J33: 2016 | K33: 0.21182591 | L33: 2.0526222 | M33: 1.714537 | N33: 16493.657 | O33: 0.30318375 | P33: 0.043307735
A34: =dataset!A34 -> 12 | B34: =dataset!B34 -> 2020 | C34: =EXP(dataset!C34) -> 0.15251235 | D34: =EXP(dataset!D34) -> 2.2665 | E34: =EXP(dataset!G34) -> 1.8574 | F34: =1000*EXP(dataset!M34) -> 9720.6094 | G34: =EXP(dataset!L34) -> 0.24965622 | H34: =EXP(dataset!J34) -> 1.0274241 | J34: 2017 | K34: 0.21485131 | L34: 2.0292593 | M34: 1.6957481 | N34: 16631.748 | O34: 0.3107347 | P34: 0.081952898
... A40: =dataset!A40 -> 13 | B40: =dataset!B40 -> 2008 | C40: =EXP(dataset!C40) -> 0.11629522 | D40: =EXP(dataset!D40) -> 2.2057 | E40: =EXP(dataset!G40) -> 1.6091 | F40: =1000*EXP(dataset!M40) -> 16756.035 | G40: =EXP(dataset!L40) -> 0.092544837 | H40: =EXP(dataset!J40) -> 1e-05 | J40: 2023 | K40: 0.22057919 | L40: 2.158337 | M40: 1.6597815 | N40: 18311.345 | O40: 0.36307324 | P40: 2.4417685
A41: =dataset!A41 -> 13 | B41: =dataset!B41 -> 2009 | C41: =EXP(dataset!C41) -> 0.11885307 | D41: =EXP(dataset!D41) -> 2.2272 | E41: =EXP(dataset!G41) -> 1.5686 | F41: =1000*EXP(dataset!M41) -> 16154.643 | G41: =EXP(dataset!L41) -> 0.10153272 | H41: =EXP(dataset!J41) -> 0.00029469238
A42: =dataset!A42 -> 13 | B42: =dataset!B42 -> 2010 | C42: =EXP(dataset!C42) -> 0.13522928 | D42: =EXP(dataset!D42) -> 2.1357 | E42: =EXP(dataset!G42) -> 1.6611 | F42: =1000*EXP(dataset!M42) -> 17564.705 | G42: =EXP(dataset!L42) -> 0.11136082 | H42: =EXP(dataset!J42) -> 0.00057705436
A43: =dataset!A43 -> 13 | B43: =dataset!B43 -> 2011 | C43: =EXP(dataset!C43) -> 0.14734259 | D43: =EXP(dataset!D43) -> 2.1359 | E43: =EXP(dataset!G43) -> 1.7595 | F43: =1000*EXP(dataset!M43) -> 18455.352 | G43: =EXP(dataset!L43) -> 0.12084885 | H43: =EXP(dataset!J43) -> 0.0025435318
A44: =dataset!A44 -> 13 | B44: =dataset!B44 -> 2012 | C44: =EXP(dataset!C44) -> 0.15856283 | D44: =EXP(dataset!D44) -> 2.0979 | E44: =EXP(dataset!G44) -> 1.6914 | F44: =1000*EXP(dataset!M44) -> 17206.098 | G44: =EXP(dataset!L44) -> 0.13010246 | H44: =EXP(dataset!J44) -> 0.0036201766
A45: =dataset!A45 -> 13 | B45: =dataset!B45 -> 2013 | C45: =EXP(dataset!C45) -> 0.15513694 | D45: =EXP(dataset!D45) -> 2.0494 | E45: =EXP(dataset!G45) -> 1.6656 | F45: =1000*EXP(dataset!M45) -> 17351.349 | G45: =EXP(dataset!L45) -> 0.13384075 | H45: =EXP(dataset!J45) -> 0.0078783147
A46: =dataset!A46 -> 13 | B46: =dataset!B46 -> 2014 | C46: =EXP(dataset!C46) -> 0.16195033 | D46: =EXP(dataset!D46) -> 2.0354 | E46: =EXP(dataset!G46) -> 1.6361 | F46: =1000*EXP(dataset!M46) -> 16504.387 | G46: =EXP(dataset!L46) -> 0.14219503 | H46: =EXP(dataset!J46) -> 0.014972599
A47: =dataset!A47 -> 13 | B47: =dataset!B47 -> 2015 | C47: =EXP(dataset!C47) -> 0.1567168 | D47: =EXP(dataset!D47) -> 2.1011 | E47: =EXP(dataset!G47) -> 1.6239 | F47: =1000*EXP(dataset!M47) -> 15074.33 | G47: =EXP(dataset!L47) -> 0.14730257 | H47: =EXP(dataset!J47) -> 0.020820976
A48: =dataset!A48 -> 13 | B48: =dataset!B48 -> 2016 | C48: =EXP(dataset!C48) -> 0.15847713 | D48: =EXP(dataset!D48) -> 2.0425 | E48: =EXP(dataset!G48) -> 1.8015 | F48: =1000*EXP(dataset!M48) -> 14115.473 | G48: =EXP(dataset!L48) -> 0.14985455 | H48: =EXP(dataset!J48) -> 0.028488128
A49: =dataset!A49 -> 13 | B49: =dataset!B49 -> 2017 | C49: =EXP(dataset!C49) -> 0.15858409 | D49: =EXP(dataset!D49) -> 2.0265 | E49: =EXP(dataset!G49) -> 1.7446 | F49: =1000*EXP(dataset!M49) -> 14040.549 | G49: =EXP(dataset!L49) -> 0.15304948 | H49: =EXP(dataset!J49) -> 0.052908569
A50: =dataset!A50 -> 13 | B50: =dataset!B50 -> 2018 | C50: =EXP(dataset!C50) -> 0.15051161 | D50: =EXP(dataset!D50) -> 2.307 | E50: =EXP(dataset!G50) -> 1.8046 | F50: =1000*EXP(dataset!M50) -> 14366.564 | G50: =EXP(dataset!L50) -> 0.15929722 | H50: =EXP(dataset!J50) -> 0.083320856
...

Sheet CV
A3: Row Labels | B3: Average of y | C3: Average of eps2 | D3: Average of y_hat | F3: Year | G3: Actual sales | H3: MSE | I3: RMSE | J3: CVt | K3: Predicted sales
A4: 2006 | B4: 0.1175124 | C4: 0.0005203685 | D4: 0.10754826 | F4: 2006 | G4: 0.1175124 | H4: 0.0005203685 | I4: =SQRT(H4) -> 0.022811587 | J4: =I4/G4 -> 0.19412068 | K4: 0.10754826
A5: 2007 | B5: 0.11945993 | C5: 0.00032299777 | D5: 0.11503293 | F5: 2007 | G5: 0.11945993 | H5: 0.00032299777 | I5: =SQRT(H5) -> 0.017972139 | J5: =I5/G5 -> 0.15044491 | K5: 0.11503293
A6: 2008 | B6: 0.12737279 | C6: 0.00026831694 | D6: 0.12546922 | F6: 2008 | G6: 0.12737279 | H6: 0.00026831694 | I6: =SQRT(H6) -> 0.016380383 | J6: =I6/G6 -> 0.1286019 | K6: 0.12546922
A7: 2009 | B7: 0.13110086 | C7: 0.00026784279 | D7: 0.13449075 | F7: 2009 | G7: 0.13110086 | H7: 0.00026784279 | I7: =SQRT(H7) -> 0.016365903 | J7: =I7/G7 -> 0.12483444 | K7: 0.13449075
A8: 2010 | B8: 0.15492585 | C8: 0.00036859367 | D8: 0.15301714 | F8: 2010 | G8: 0.15492585 | H8: 0.00036859367 | I8: =SQRT(H8) -> 0.019198793 | J8: =I8/G8 -> 0.12392246 | K8: 0.15301714
A9: 2011 | B9: 0.17681577 | C9: 0.00045794633 | D9: 0.17184915 | F9: 2011 | G9: 0.17681577 | H9: 0.00045794633 | I9: =SQRT(H9) -> 0.021399681 | J9: =I9/G9 -> 0.12102812 | K9: 0.17184915
A10: 2012 | B10: 0.19892608 | C10: 0.00044215761 | D10: 0.19264259 | F10: 2012 | G10: 0.19892608 | H10: 0.00044215761 | I10: =SQRT(H10) -> 0.021027544 | J10: =I10/G10 -> 0.10570531 | K10: 0.19264259
A11: 2013 | B11: 0.2014577 | C11: 0.00040051474 | D11: 0.20024489 | F11: 2013 | G11: 0.2014577 | H11: 0.00040051474 | I11: =SQRT(H11) -> 0.020012864 | J11: =I11/G11 -> 0.099340281 | K11: 0.20024489
A12: 2014 | B12: 0.21624676 | C12: 0.00037757082 | D12: 0.21229744 | F12: 2014 | G12: 0.21624676 | H12: 0.00037757082 | I12: =SQRT(H12) -> 0.019431182 | J12: =I12/G12 -> 0.08985652 | K12: 0.21229744
A13: 2015 | B13: 0.20535221 | C13: 0.00039241622 | D13: 0.20346724 | F13: 2015 | G13: 0.20535221 | H13: 0.00039241622 | I13: =SQRT(H13) -> 0.019809498 | J13: =I13/G13 -> 0.096465962 | K13: 0.20346724
A14: 2016 | B14: 0.21182591 | C14: 0.00034538156 | D14: 0.21117083 | F14: 2016 | G14: 0.21182591 | H14: 0.00034538156 | I14: =SQRT(H14) -> 0.018584444 | J14: =I14/G14 -> 0.087734518 | K14: 0.21117083
A15: 2017 | B15: 0.21485131 | C15: 0.00041669758 | D15: 0.21820558 | F15: 2017 | G15: 0.21485131 | H15: 0.00041669758 | I15: =SQRT(H15) -> 0.020413172 | J15: =I15/G15 -> 0.095010695 | K15: 0.21820558
... A21: 2023 | B21: 0.22057919 | C21: 0.00059735741 | D21: 0.21663938 | F21: 2023 | G21: 0.22057919 | H21: 0.00059735741 | I21: =SQRT(H21) -> 0.024440896 | J21: =I21/G21 -> 0.11080328 | K21: 0.21663938
A22: Grand Total | B22: 0.18203375 | C22: 0.00047877476 | D22: 0.18264618 | N22: Diag
N23: 0 | O23: 0
N24: 0.4 | O24: 0.4
A30: Row Labels | B30: Average of y | C30: Average of eps2 | D30: Average of y_hat | E30: State ID | F30: State | G30: Actual sales | H30: MSE | I30: Predicted sales | J30: RMSE | K30: CV(RMSE)s
A31: 11 | B31: 0.21226523 | C31: 4.3486537e-05 | D31: 0.21120261 | E31: 33 | F31: RJ | G31: 0.13013742 | H31: 0.0022175102 | I31: 0.17281645 | J31: =SQRT(H31) -> 0.047090447 | K31: =J31/G31 -> 0.36185169
A32: 12 | B32: 0.14478576 | C32: 8.4067264e-05 | D32: 0.14940515 | E32: 51 | F32: MT | G32: 0.15994045 | H32: 0.0010992058 | I32: 0.18281525 | J32: =SQRT(H32) -> 0.033154273 | K32: =J32/G32 -> 0.20729137
A33: 13 | B33: 0.14265568 | C33: 0.00058552753 | D33: 0.11937551 | E33: 13 | F33: AM | G33: 0.14265568 | H33: 0.00058552753 | I33: 0.11937551 | J33: =SQRT(H33) -> 0.024197676 | K33: =J33/G33 -> 0.16962294
A34: 14 | B34: 0.22080629 | C34: 0.00042858529 | D34: 0.21379013 | E34: 53 | F34: DF | G34: 0.3555864 | H34: 0.0034204423 | I34: 0.3031681 | J34: =SQRT(H34) -> 0.058484548 | K34: =J34/G34 -> 0.16447352
A35: 15 | B35: 0.11806836 | C35: 1.8823321e-05 | D35: 0.12122362 | E35: 23 | F35: CE | G35: 0.12590131 | H35: 0.00039014731 | I35: 0.14515454 | J35: =SQRT(H35) -> 0.019752147 | K35: =J35/G35 -> 0.15688595
A36: 16 | B36: 0.17948894 | C36: 0.00015525087 | D36: 0.18477785 | E36: 35 | F36: SP | G36: 0.20153995 | H36: 0.00095107149 | I36: 0.21500863 | J36: =SQRT(H36) -> 0.030839447 | K36: =J36/G36 -> 0.15301903
A37: 17 | B37: 0.2011252 | C37: 0.0003434033 | D37: 0.18494742 | E37: 41 | F37: PR | G37: 0.22394056 | H37: 0.00074223981 | I37: 0.24501905 | J37: =SQRT(H37) -> 0.027244078 | K37: =J37/G37 -> 0.12165763
A38: 21 | B38: 0.10998058 | C38: 5.6678175e-05 | D38: 0.10302243 | E38: 52 | F38: GO | G38: 0.19555928 | H38: 0.00049293506 | I38: 0.1985088 | J38: =SQRT(H38) -> 0.022202141 | K38: =J38/G38 -> 0.11353151
A39: 22 | B39: 0.14364917 | C39: 5.9288121e-05 | D39: 0.14586773 | E39: 26 | F39: PE | G39: 0.12699672 | H39: 0.00018293737 | I39: 0.13911742 | J39: =SQRT(H39) -> 0.013525434 | K39: =J39/G39 -> 0.10650223
A40: 23 | B40: 0.12590131 | C40: 0.00039014731 | D40: 0.14515454 | E40: 31 | F40: MG | G40: 0.18750115 | H40: 0.00038681951 | I40: 0.17866006 | J40: =SQRT(H40) -> 0.019667728 | K40: =J40/G40 -> 0.10489391
A41: 24 | B41: 0.15623371 | C41: 2.0933525e-05 | D41: 0.15575828 | E41: 14 | F41: RR | G41: 0.22080629 | H41: 0.00042858529 | I41: 0.21379013 | J41: =SQRT(H41) -> 0.020702302 | K41: =J41/G41 -> 0.093757755
A42: 25 | B42: 0.1445851 | C42: 1.7570996e-05 | D42: 0.14428139 | E42: 17 | F42: TO | G42: 0.2011252 | H42: 0.0003434033 | I42: 0.18494742 | J42: =SQRT(H42) -> 0.018531144 | K42: =J42/G42 -> 0.092137356
... A48: 32 | B48: 0.20924913 | C48: 0.00010497863 | D48: 0.21197645 | E48: 50 | F48: MS | G48: 0.23228388 | H48: 0.00016023813 | I48: 0.23937543 | J48: =SQRT(H48) -> 0.01265852 | K48: =J48/G48 -> 0.054495904
A49: 33 | B49: 0.13013742 | C49: 0.0022175102 | D49: 0.17281645 | E49: 22 | F49: PI | G49: 0.14364917 | H49: 5.9288121e-05 | I49: 0.14586773 | J49: =SQRT(H49) -> 0.007699878 | K49: =J49/G49 -> 0.053601967 | N49: Mean y | O49: MSE | P49: RMSE | Q49: CV(RMSE)
A50: 35 | B50: 0.20153995 | C50: 0.00095107149 | D50: 0.21500863 | E50: 32 | F50: ES | G50: 0.20924913 | H50: 0.00010497863 | I50: 0.21197645 | J50: =SQRT(H50) -> 0.010245908 | K50: =J50/G50 -> 0.048965116 | N50: 0.18203375 | O50: 0.00047877476 | P50: =SQRT(O50) -> 0.021880922 | Q50: =P50/N50 -> 0.12020256
A51: 41 | B51: 0.22394056 | C51: 0.00074223981 | D51: 0.24501905 | E51: 27 | F51: AL | G51: 0.10911358 | H51: 2.1206966e-05 | I51: 0.11230514 | J51: =SQRT(H51) -> 0.0046051022 | K51: =J51/G51 -> 0.042204666
A52: 42 | B52: 0.34249588 | C52: 0.00072044418 | D52: 0.32325194 | E52: 15 | F52: PA | G52: 0.11806836 | H52: 1.8823321e-05 | I52: 0.12122362 | J52: =SQRT(H52) -> 0.0043385852 | K52: =J52/G52 -> 0.036746384
A53: 43 | B53: 0.27322144 | C53: 7.8783941e-05 | D53: 0.27437006 | E53: 28 | F53: SE | G53: 0.14784791 | H53: 2.5235593e-05 | I53: 0.14613939 | J53: =SQRT(H53) -> 0.005023504 | K53: =J53/G53 -> 0.033977512
A54: 50 | B54: 0.23228388 | C54: 0.00016023813 | D54: 0.23937543 | E54: 43 | F54: RS | G54: 0.27322144 | H54: 7.8783941e-05 | I54: 0.27437006 | J54: =SQRT(H54) -> 0.0088760318 | K54: =J54/G54 -> 0.032486586
A55: 51 | B55: 0.15994045 | C55: 0.0010992058 | D55: 0.18281525 | E55: 11 | F55: RO | G55: 0.21226523 | H55: 4.3486537e-05 | I55: 0.21120261 | J55: =SQRT(H55) -> 0.0065944323 | K55: =J55/G55 -> 0.031066945
A56: 52 | B56: 0.19555928 | C56: 0.00049293506 | D56: 0.1985088 | E56: 24 | F56: RN | G56: 0.15623371 | H56: 2.0933525e-05 | I56: 0.15575828 | J56: =SQRT(H56) -> 0.0045753169 | K56: =J56/G56 -> 0.029285081
A57: 53 | B57: 0.3555864 | C57: 0.0034204423 | D57: 0.3031681 | E57: 25 | F57: PB | G57: 0.1445851 | H57: 1.7570996e-05 | I57: 0.14428139 | J57: =SQRT(H57) -> 0.0041917772 | K57: =J57/G57 -> 0.028991765
...
